025-05-03 18:47:45,425 - ERROR - ERROR: [generic] Unable to download webpage: HTTP Error 403: Forbidden (caused by <HTTPError 403: Forbidden>)
2025-05-03 18:47:45,425 - ERROR -   File "/home/runner/workspace/.pythonlibs/lib/python3.11/site-packages/yt_dlp/extractor/common.py", line 748, in extract
    ie_result = self._real_extract(url)
                ^^^^^^^^^^^^^^^^^^^^^^^
  File "/home/runner/workspace/.pythonlibs/lib/python3.11/site-packages/yt_dlp/extractor/generic.py", line 2418, in _real_extract
    full_response = self._request_webpage(url, video_id, headers=filter_dict({
                    ^^^^^^^^^^^^^^^^^^^^^^^^^^^^^^^^^^^^^^^^^^^^^^^^^^^^^^^^^^
  File "/home/runner/workspace/.pythonlibs/lib/python3.11/site-packages/yt_dlp/extractor/common.py", line 917, in _request_webpage
    raise ExtractorError(errmsg, cause=err)

  File "/home/runner/workspace/.pythonlibs/lib/python3.11/site-packages/yt_dlp/networking/_urllib.py", line 400, in _send
    res = opener.open(urllib_req, timeout=self._calculate_timeout(request))
          ^^^^^^^^^^^^^^^^^^^^^^^^^^^^^^^^^^^^^^^^^^^^^^^^^^^^^^^^^^^^^^^^^
  File "/nix/store/clx0mcir7qw8zk36zbr4jra789g3knf6-python3-3.11.10/lib/python3.11/urllib/request.py", line 525, in open
    response = meth(req, response)
               ^^^^^^^^^^^^^^^^^^^
  File "/nix/store/clx0mcir7qw8zk36zbr4jra789g3knf6-python3-3.11.10/lib/python3.11/urllib/request.py", line 634, in http_response
    response = self.parent.error(
               ^^^^^^^^^^^^^^^^^^
  File "/nix/store/clx0mcir7qw8zk36zbr4jra789g3knf6-python3-3.11.10/lib/python3.11/urllib/request.py", line 563, in error
    return self._call_chain(*args)
           ^^^^^^^^^^^^^^^^^^^^^^^
  File "/nix/store/clx0mcir7qw8zk36zbr4jra789g3knf6-python3-3.11.10/lib/python3.11/urllib/request.py", line 496, in _call_chain
    result = func(*args)
             ^^^^^^^^^^^
  File "/nix/store/clx0mcir7qw8zk36zbr4jra789g3knf6-python3-3.11.10/lib/python3.11/urllib/request.py", line 643, in http_error_default
    raise HTTPError(req.full_url, code, msg, hdrs, fp)
urllib.error.HTTPError: HTTP Error 403: Forbidden

The above exception was the direct cause of the following exception:

Traceback (most recent call last):
  File "/home/runner/workspace/.pythonlibs/lib/python3.11/site-packages/yt_dlp/extractor/common.py", line 904, in _request_webpage
    return self._downloader.urlopen(self._create_request(url_or_request, data, headers, query, extensions))
           ^^^^^^^^^^^^^^^^^^^^^^^^^^^^^^^^^^^^^^^^^^^^^^^^^^^^^^^^^^^^^^^^^^^^^^^^^^^^^^^^^^^^^^^^^^^^^^^^
  File "/home/runner/workspace/.pythonlibs/lib/python3.11/site-packages/yt_dlp/YoutubeDL.py", line 4186, in urlopen
    return self._request_director.send(req)
           ^^^^^^^^^^^^^^^^^^^^^^^^^^^^^^^^
  File "/home/runner/workspace/.pythonlibs/lib/python3.11/site-packages/yt_dlp/networking/common.py", line 117, in send
    response = handler.send(request)
               ^^^^^^^^^^^^^^^^^^^^^
  File "/home/runner/workspace/.pythonlibs/lib/python3.11/site-packages/yt_dlp/networking/_helper.py", line 208, in wrapper
    return func(self, *args, **kwargs)
           ^^^^^^^^^^^^^^^^^^^^^^^^^^^
  File "/home/runner/workspace/.pythonlibs/lib/python3.11/site-packages/yt_dlp/networking/common.py", line 359, in send
    return self._send(request)
           ^^^^^^^^^^^^^^^^^^^
  File "/home/runner/workspace/.pythonlibs/lib/python3.11/site-packages/yt_dlp/networking/_urllib.py", line 405, in _send
    raise HTTPError(UrllibResponseAdapter(e.fp), redirect_loop='redirect error' in str(e)) from e
yt_dlp.networking.exceptions.HTTPError: HTTP Error 403: Forbidden

Downloaded ━━━━━━━━━━━━━━━━━━━━━━━━━━━━━━━━━━━━━━━━━━━━━━━━━━━━━━━━━━ 1/1 0:00:06

Téléchargement terminé !

Appuyez sur Entrée pour continuer..